Workbook
Name LIM_INS_DC: 'Equipment and Limits'!$D$19
Name LIM_INS_AC: 'Equipment and Limits'!$D$20
Name LIM_VOC_DEV: 'Equipment and Limits'!$D$21
Name LIM_EARTH: 'Equipment and Limits'!$D$22
Name LIM_VNOM: 'Equipment and Limits'!$D$23
Name LIM_VTOL: 'Equipment and Limits'!$D$24
Name LIM_FNOM: 'Equipment and Limits'!$D$25
Name LIM_FTOL: 'Equipment and Limits'!$D$26
Name LIM_DT: 'Equipment and Limits'!$D$27

Sheet Cover
B2: SOLAR PV SYSTEM INSTALLATION COMMISSIONING REPORT
B4: Regen Renewables (Pvt) Ltd. · 31/10 Castle Street, Colombo 8, Sri Lanka · regen.lk
B6: 1. GENERAL DETAILS
B7: Project Name | E7: Document No.
B8: Address | E8: Revision No. | F8: Rev 0
B9: Contact Person Name | E9: Commissioning Date
B10: Telephone — Fixed | E10: Telephone — Mobile
B11: E-Mail | E11: Weather Condition
B12: Electricity Bill Available | E12: Client
B14: 2. PV SYSTEM & UTILITY DETAILS
B15: EPC / Installation Contractor | E15: Inverter Brand & Model
B16: PV System Capacity (kWp) | E16: Number of Inverters
B17: System AC Capacity (kW) | E17: Roof Structure
B18: PV System Connection Method | E18: Utility System Voltage
B19: Utility Supplier | E19: Utility Supplier's Branch Office
B20: Utility Account No. | E20: Installation Type
B22: 3. PV PANEL DETAILS
B23: PV Module Brand & Model | E23: Rated Power (Wp)
B24: Voc / Vmp (V) | E24: Imp / Isc (A)
B25: Number of Panels | E25: Number of Strings
B27: 4. PREPARED / REVIEWED / APPROVED
B28: Prepared By (Name / Company) | E28: Reviewed By (Name / Company)
B29: Approved By (Name / Company) | E29: Approval Date
B31: 5. HOW THIS WORKBOOK WORKS
B32: • Yellow cells = fill in on site. Grey cells = calculated automatically (Pass / Fail, totals, deviations) — do not type over them.
B33: • Every reading is entered ONCE, in its own table. The Summary sheet collects all results automatically, and the project name is picked up from this Cover on every sheet.
B34: • Acceptance limits (minimum insulation, earth resistance, voltage / frequency window, thermal ΔT) are on “Equipment and Limits”. They are defaults — edit them to your company / utility standard.
B35: • Inverters differ per project: copy the “DC INV 01” tab (right-click → Move or Copy → Create a copy), rename it, then add a matching row on the Summary sheet. MPPT / String columns are free-text, so any layout works.
B36: • Insulation testers that show “>” or “OL”: type the highest number displayed (e.g. 999). Single-phase inverters: type N/A in the L2 / L3 insulation cells.
B37: • Battery Test applies to hybrid systems only — set “Applicable” to Yes on the Summary sheet when a battery is installed.
B39: 6. REPORT CONTENTS
B40: 1 | C40: Summary (auto)
B41: 2 | C41: Equipment and Limits
B42: 3 | C42: Visual Inspection
B43: 4 | C43: Inverters and Panel
B44: 5 | C44: DC String Tests — one sheet per inverter
B45: 6 | C45: AC Output (incl. grid no-load)
B46: 7 | C46: AC Insulation and Earthing
B47: 8 | C47: Thermal Imaging
B48: 9 | C48: Battery (hybrid only)
...

Sheet Summary
B2: COMMISSIONING SUMMARY (calculated automatically)
B4: ="Project: "&IF(Cover!$C$7="","(enter on Cover sheet)",Cover!$C$7)&" | Regen Renewables (Pvt) Ltd."
B6: Project | D6: =IF(Cover!$C$7="","",Cover!$C$7)
B7: Commissioning Date | D7: =IF(Cover!$F$9="","",Cover!$F$9)
B9: No. | C9: Section | D9: Applicable | E9: Pass | F9: Fail | G9: Open | H9: Status | I9: Remarks
B10: 1 | C10: Visual & Mechanical Inspection | D10: Yes | E10: =COUNTIF('Visual Inspection'!$D$7:$D$42,"Pass") | F10: =COUNTIF('Visual Inspection'!$D$7:$D$42,"Fail") | G10: =COUNTA('Visual Inspection'!$C$7:$C$42)-COUNTIF('Visual Inspection'!$D$7:$D$42,"Pass")-COUNTIF('Visual Inspection'!$D$7:$D$42,"Fail")-COUNTIF('Visual Inspection'!$D$7:$D$42,"N/A") | H10: =IF(D10="No","N/A",IF(F10>0,"FAIL",IF(G10>0,"IN PROGRESS",IF(E10>0,"PASS","NOT TESTED"))))
B11: 2 | C11: DC String Tests — INV 01 | D11: Yes | E11: =COUNTIF('DC INV 01'!$N$15:$N$50,"Pass") | F11: =COUNTIF('DC INV 01'!$N$15:$N$50,"Fail") | G11: =COUNTIF('DC INV 01'!$N$15:$N$50,"Incomplete") | H11: =IF(D11="No","N/A",IF(F11>0,"FAIL",IF(G11>0,"IN PROGRESS",IF(E11>0,"PASS","NOT TESTED"))))
B12: 3 | C12: DC String Tests — INV 02 | D12: Yes | E12: =COUNTIF('DC INV 02'!$N$15:$N$50,"Pass") | F12: =COUNTIF('DC INV 02'!$N$15:$N$50,"Fail") | G12: =COUNTIF('DC INV 02'!$N$15:$N$50,"Incomplete") | H12: =IF(D12="No","N/A",IF(F12>0,"FAIL",IF(G12>0,"IN PROGRESS",IF(E12>0,"PASS","NOT TESTED"))))
B13: 4 | C13: AC Output (grid no-load & inverters) | D13: Yes | E13: =COUNTIF('AC Output'!$N$11:$N$22,"Pass") | F13: =COUNTIF('AC Output'!$N$11:$N$22,"Fail") | G13: =COUNTIF('AC Output'!$N$11:$N$22,"Incomplete") | H13: =IF(D13="No","N/A",IF(F13>0,"FAIL",IF(G13>0,"IN PROGRESS",IF(E13>0,"PASS","NOT TESTED"))))
B14: 5 | C14: AC Insulation Resistance | D14: Yes | E14: =COUNTIF('AC Insulation and Earthing'!$N$10:$N$21,"Pass") | F14: =COUNTIF('AC Insulation and Earthing'!$N$10:$N$21,"Fail") | G14: =COUNTIF('AC Insulation and Earthing'!$N$10:$N$21,"Incomplete") | H14: =IF(D14="No","N/A",IF(F14>0,"FAIL",IF(G14>0,"IN PROGRESS",IF(E14>0,"PASS","NOT TESTED"))))
B15: 6 | C15: Earthing | D15: Yes | E15: =COUNTIF('AC Insulation and Earthing'!$G$26:$G$33,"Pass") | F15: =COUNTIF('AC Insulation and Earthing'!$G$26:$G$33,"Fail") | G15: =0 | H15: =IF(D15="No","N/A",IF(F15>0,"FAIL",IF(G15>0,"IN PROGRESS",IF(E15>0,"PASS","NOT TESTED"))))
B16: 7 | C16: Thermal Imaging (panels, inverters, switchgear) | D16: Yes | E16: =COUNTIF('Thermal Imaging'!$H$12:$H$21,"Pass")+COUNTIF('Thermal Imaging'!$H$25:$H$32,"Pass")+COUNTIF('Thermal Imaging'!$H$36:$H$44,"Pass") | F16: =COUNTIF('Thermal Imaging'!$H$12:$H$21,"Fail")+COUNTIF('Thermal Imaging'!$H$25:$H$32,"Fail")+COUNTIF('Thermal Imaging'!$H$36:$H$44,"Fail") | G16: =COUNTIF('Thermal Imaging'!$H$12:$H$21,"Incomplete")+COUNTIF('Thermal Imaging'!$H$25:$H$32,"Incomplete")+COUNTIF('Thermal Imaging'!$H$36:$H$44,"Incomplete") | H16: =IF(D16="No","N/A",IF(F16>0,"FAIL",IF(G16>0,"IN PROGRESS",IF(E16>0,"PASS","NOT TESTED"))))
B17: 8 | C17: Battery Test (hybrid systems only) | D17: No | E17: =COUNTIF('Battery'!$H$14:$H$29,"Pass")+COUNTIF('Battery'!$F$33:$F$41,"Pass") | F17: =COUNTIF('Battery'!$H$14:$H$29,"Fail")+COUNTIF('Battery'!$F$33:$F$41,"Fail") | G17: =COUNTA('Battery'!$C$33:$C$41)-COUNTIF('Battery'!$F$33:$F$41,"Pass")-COUNTIF('Battery'!$F$33:$F$41,"Fail")-COUNTIF('Battery'!$F$33:$F$41,"N/A") | H17: =IF(D17="No","N/A",IF(F17>0,"FAIL",IF(G17>0,"IN PROGRESS",IF(E17>0,"PASS","NOT TESTED"))))
B18: 9 | C18: Protection & Grid Settings | D18: Yes | E18: =COUNTIF('Protection and Grid'!$F$7:$F$20,"Pass") | F18: =COUNTIF('Protection and Grid'!$F$7:$F$20,"Fail") | G18: =COUNTA('Protection and Grid'!$C$7:$C$20)-COUNTIF('Protection and Grid'!$F$7:$F$20,"Pass")-COUNTIF('Protection and Grid'!$F$7:$F$20,"Fail")-COUNTIF('Protection and Grid'!$F$7:$F$20,"N/A") | H18: =IF(D18="No","N/A",IF(F18>0,"FAIL",IF(G18>0,"IN PROGRESS",IF(E18>0,"PASS","NOT TESTED"))))
B19: 10 | C19: Punch List — all items closed | D19: Yes | E19: =COUNTIF('Punch List'!$K$7:$K$24,"Closed") | F19: =0 | G19: =COUNTIF('Punch List'!$K$7:$K$24,"Open")+COUNTIF('Punch List'!$K$7:$K$24,"In Progress") | H19: =IF(D19="No","N/A",IF(G19>0,"IN PROGRESS","PASS"))
B21: OVERALL RESULT | H21: =IF(COUNTIF(H10:H19,"FAIL")>0,"FAIL",IF(COUNTIF(H10:H19,"IN PROGRESS")+COUNTIF(H10:H19,"NOT TESTED")>0,"INCOMPLETE","PASS"))
B23: Added another inverter? Copy a DC sheet, then insert a row here and point it at the new sheet’s Result column (column N, rows 15–50).

Sheet Equipment and Limits
B2: TEST EQUIPMENT & ACCEPTANCE LIMITS
B4: ="Project: "&IF(Cover!$C$7="","(enter on Cover sheet)",Cover!$C$7)&" | Regen Renewables (Pvt) Ltd."
B6: TEST EQUIPMENT REGISTER — recorded once, applies to every test in this report
B7: No. | C7: Instrument | D7: Model / Make | E7: Serial No. | F7: Calibrated On | G7: Calibration Due | H7: Used For
B8: 1 | C8: Insulation Resistance Tester | H8: DC & AC insulation tests
B9: 2 | C9: Digital Multimeter / Clamp Meter | H9: Voltage, current, polarity
B10: 3 | C10: PV String Tester / I-V Curve Tracer | H10: Voc, Isc, string current
B11: 4 | C11: Digital Earth Tester | D11: 4105A / KYORITSU | H11: Earthing test
B12: 5 | C12: Thermal Imaging Camera | H12: Panels, inverters, switchgear
B13: 6 | C13: Power / Energy Analyser | H13: AC output, PF, frequency
B14: 7 | C14: Irradiance Meter | H14: Irradiance during on-load tests
B15: 8 | C15: Other
B17: ACCEPTANCE LIMITS — defaults, edit to match your company / utility standard
B18: No. | C18: Parameter | D18: Value | E18: Unit | F18: Used in
B19: 1 | C19: DC insulation resistance — minimum | D19: 1 | E19: MΩ | F19: DC String Tests
B20: 2 | C20: AC insulation resistance — minimum | D20: 1 | E20: MΩ | F20: AC Insulation and Earthing
B21: 3 | C21: String Voc deviation within same MPPT / module count — maximum | D21: 0.05 | E21: % | F21: DC String Tests
B22: 4 | C22: Earth resistance — maximum | D22: 5 | E22: Ω | F22: AC Insulation and Earthing
B23: 5 | C23: Nominal phase voltage (L–N) | D23: 230 | E23: V | F23: AC Output
B24: 6 | C24: Voltage tolerance (±) | D24: 0.1 | E24: % | F24: AC Output
B25: 7 | C25: Nominal frequency | D25: 50 | E25: Hz | F25: AC Output
B26: 8 | C26: Frequency tolerance (±) | D26: 1 | E26: Hz | F26: AC Output
B27: 9 | C27: Thermal ΔT above ambient — maximum | D27: 20 | E27: °C | F27: Thermal Imaging

Sheet Visual Inspection
B2: VISUAL & MECHANICAL INSPECTION CHECKLIST
B4: ="Project: "&IF(Cover!$C$7="","(enter on Cover sheet)",Cover!$C$7)&" | Regen Renewables (Pvt) Ltd."
B6: No. | C6: Inspection Item | D6: Status | E6: Remarks
B7: A. PV Modules & Mounting Structure
B8: 1 | C8: Modules free of physical damage (cracks, hot spots, delamination)
B9: 2 | C9: Modules clean and free of shading obstructions
B10: 3 | C10: Mounting structure secure, level and correctly torqued
B11: 4 | C11: Module clamps / bolts torqued to spec, no loose fixings
B12: 5 | C12: Structure and module frames bonded to earthing system
B13: B. DC Cabling
B14: 6 | C14: DC cables routed and dressed neatly, no sharp bends
B15: 7 | C15: Cables secured with UV-rated cable ties / clips
B16: 8 | C16: MC4 (or equivalent) connectors fully locked, no exposed conductor
B17: 9 | C17: String / cable labelling complete and legible
B18: 10 | C18: Cable entry points and conduits sealed (IP rated)
B19: C. Inverter & DC Protection
B20: 11 | C20: Inverter securely mounted, correct orientation and clearance
B21: 12 | C21: Ventilation / cooling clearance around inverter as per manual
B22: 13 | C22: Cable glands sealed, unused entries blanked off
B23: 14 | C23: DC surge protection device (SPD) fitted and indicator normal
B24: 15 | C24: DC isolator / switch labelled and operates freely
B25: 16 | C25: Inverter display / status LEDs functioning normally
B26: D. AC Side & Main Panel
B27: 17 | C27: AC cable terminations tight and correctly torqued
B28: 18 | C28: AC circuit breaker rating matches design / datasheet
B29: 19 | C29: AC isolator accessible and labelled
B30: 20 | C30: AC cable and circuit labelling complete
B31: 21 | C31: Energy meter / CT connections correct and secure
B32: E. Earthing & Lightning Protection
B33: 22 | C33: Earth pit(s) installed and accessible for testing
B34: 23 | C34: Earth cable size / type as per design
B35: 24 | C35: Equipotential bonding complete across all metallic parts
B36: 25 | C36: Lightning / surge protection installed where specified
B37: F. Safety & Signage
B38: 26 | C38: Danger / warning labels posted at DC & AC points
B39: 27 | C39: Single line diagram (SLD) posted at site / inverter room
B40: 28 | C40: Fire extinguisher (CO2 / DCP, rated for electrical) available
B41: 29 | C41: PPE available for O&M personnel
B42: 30 | C42: Emergency shutdown procedure posted
B44: Inspected By
...

Sheet Inverters and Panel
B2: INVERTER REGISTER & MAIN PANEL DETAILS
B4: ="Project: "&IF(Cover!$C$7="","(enter on Cover sheet)",Cover!$C$7)&" | Regen Renewables (Pvt) Ltd."
B6: INVERTER REGISTER — one row per inverter (strings / PV modules per inverter are totalled on each DC String Test sheet)
B7: No. | C7: Location / Room | D7: Make | E7: Model | F7: Serial No. | G7: Rated Power (kW) | H7: DC SPD (Y/N) | I7: DC SPD Model | J7: DC Isolator Qty | K7: DC Isolator Rating | L7: DC Cable (size / type) | M7: AC Isolator (Y/N) | N7: AC Isolator Rating | O7: Remarks
B8: 1
B9: 2
B10: 3
B11: 4
B12: 5
B13: 6
B14: 7
B15: 8
B16: 9
B17: 10
B19: MAIN ELECTRICAL PANEL & CABLE DETAILS
B20: Main panel location | H20: Energy meter serial no.
B21: Main breaker make / model | H21: CT ratio (if used)
B22: Main breaker rating (A) | H22: RCD / ELCB rating (mA)
B23: Enclosure IP rating | H23: AC cable: inverter → panel (size / type / length)
B24: AC SPD fitted (Y/N) | H24: AC cable: panel → utility (size / type / length)
B25: Energy meter make / model | H25: Earth conductor size

Sheet DC INV 01
B2: DC STRING TEST — INV 01
B4: ="Project: "&IF(Cover!$C$7="","(enter on Cover sheet)",Cover!$C$7)&" | Regen Renewables (Pvt) Ltd."
B6: INVERTER DETAILS
B7: Inverter No. | F7: INV 01 | I7: Inverter Location / Room
B8: Make / Model | I8: Serial No.
B9: Rated Capacity (kW) | I9: Date / Time
B10: Tested By | I10: Weather / Irradiance (W/m²)
B11: Total Strings Listed | F11: =COUNT(E15:E50) | I11: Total PV Modules | L11: =SUM(E15:E50)
B12: STRING TESTS — each string is entered ONCE (MPPT / string / module count are not repeated)
B13: STRING DETAILS | F13: NO-LOAD (before energising) | L13: ON-LOAD | N13: RESULT
B14: No. | C14: MPPT | D14: String | E14: PV Modules | F14: Voc (V) | G14: Voc dev. vs group | H14: Insulation + to Earth (MΩ) | I14: Insulation – to Earth (MΩ) | J14: Insulation + to – (MΩ) | K14: Polarity | L14: Operating Voltage (V) | M14: String Current (A) | N14: Result | O14: Remarks
B15: 1 | G15: =IF(NOT(ISNUMBER(F15)),"",IFERROR(F15/IF(AND(C15<>"",E15<>""),AVERAGEIFS(F$15:F$50,C$15:C$50,C15,E$15:E$50,E15),AVERAGE(F$15:F$50))-1,"")) | N15: =IF(COUNTA(F15,H15:M15)=0,"",IF(OR(K15="Reverse",AND(COUNT(H15:J15)>0,MIN(H15:J15)<LIM_INS_DC),IF(ISNUMBER(G15),ABS(G15)>LIM_VOC_DEV,FALSE)),"Fail",IF(AND(ISNUMBER(F15),COUNT(H15:J15)=3,K15="OK"),"Pass","Incomplete")))
B16: 2 | G16: =IF(NOT(ISNUMBER(F16)),"",IFERROR(F16/IF(AND(C16<>"",E16<>""),AVERAGEIFS(F$15:F$50,C$15:C$50,C16,E$15:E$50,E16),AVERAGE(F$15:F$50))-1,"")) | N16: =IF(COUNTA(F16,H16:M16)=0,"",IF(OR(K16="Reverse",AND(COUNT(H16:J16)>0,MIN(H16:J16)<LIM_INS_DC),IF(ISNUMBER(G16),ABS(G16)>LIM_VOC_DEV,FALSE)),"Fail",IF(AND(ISNUMBER(F16),COUNT(H16:J16)=3,K16="OK"),"Pass","Incomplete")))
B17: 3 | G17: =IF(NOT(ISNUMBER(F17)),"",IFERROR(F17/IF(AND(C17<>"",E17<>""),AVERAGEIFS(F$15:F$50,C$15:C$50,C17,E$15:E$50,E17),AVERAGE(F$15:F$50))-1,"")) | N17: =IF(COUNTA(F17,H17:M17)=0,"",IF(OR(K17="Reverse",AND(COUNT(H17:J17)>0,MIN(H17:J17)<LIM_INS_DC),IF(ISNUMBER(G17),ABS(G17)>LIM_VOC_DEV,FALSE)),"Fail",IF(AND(ISNUMBER(F17),COUNT(H17:J17)=3,K17="OK"),"Pass","Incomplete")))
B18: 4 | G18: =IF(NOT(ISNUMBER(F18)),"",IFERROR(F18/IF(AND(C18<>"",E18<>""),AVERAGEIFS(F$15:F$50,C$15:C$50,C18,E$15:E$50,E18),AVERAGE(F$15:F$50))-1,"")) | N18: =IF(COUNTA(F18,H18:M18)=0,"",IF(OR(K18="Reverse",AND(COUNT(H18:J18)>0,MIN(H18:J18)<LIM_INS_DC),IF(ISNUMBER(G18),ABS(G18)>LIM_VOC_DEV,FALSE)),"Fail",IF(AND(ISNUMBER(F18),COUNT(H18:J18)=3,K18="OK"),"Pass","Incomplete")))
B19: 5 | G19: =IF(NOT(ISNUMBER(F19)),"",IFERROR(F19/IF(AND(C19<>"",E19<>""),AVERAGEIFS(F$15:F$50,C$15:C$50,C19,E$15:E$50,E19),AVERAGE(F$15:F$50))-1,"")) | N19: =IF(COUNTA(F19,H19:M19)=0,"",IF(OR(K19="Reverse",AND(COUNT(H19:J19)>0,MIN(H19:J19)<LIM_INS_DC),IF(ISNUMBER(G19),ABS(G19)>LIM_VOC_DEV,FALSE)),"Fail",IF(AND(ISNUMBER(F19),COUNT(H19:J19)=3,K19="OK"),"Pass","Incomplete")))
B20: 6 | G20: =IF(NOT(ISNUMBER(F20)),"",IFERROR(F20/IF(AND(C20<>"",E20<>""),AVERAGEIFS(F$15:F$50,C$15:C$50,C20,E$15:E$50,E20),AVERAGE(F$15:F$50))-1,"")) | N20: =IF(COUNTA(F20,H20:M20)=0,"",IF(OR(K20="Reverse",AND(COUNT(H20:J20)>0,MIN(H20:J20)<LIM_INS_DC),IF(ISNUMBER(G20),ABS(G20)>LIM_VOC_DEV,FALSE)),"Fail",IF(AND(ISNUMBER(F20),COUNT(H20:J20)=3,K20="OK"),"Pass","Incomplete")))
B21: 7 | G21: =IF(NOT(ISNUMBER(F21)),"",IFERROR(F21/IF(AND(C21<>"",E21<>""),AVERAGEIFS(F$15:F$50,C$15:C$50,C21,E$15:E$50,E21),AVERAGE(F$15:F$50))-1,"")) | N21: =IF(COUNTA(F21,H21:M21)=0,"",IF(OR(K21="Reverse",AND(COUNT(H21:J21)>0,MIN(H21:J21)<LIM_INS_DC),IF(ISNUMBER(G21),ABS(G21)>LIM_VOC_DEV,FALSE)),"Fail",IF(AND(ISNUMBER(F21),COUNT(H21:J21)=3,K21="OK"),"Pass","Incomplete")))
B22: 8 | G22: =IF(NOT(ISNUMBER(F22)),"",IFERROR(F22/IF(AND(C22<>"",E22<>""),AVERAGEIFS(F$15:F$50,C$15:C$50,C22,E$15:E$50,E22),AVERAGE(F$15:F$50))-1,"")) | N22: =IF(COUNTA(F22,H22:M22)=0,"",IF(OR(K22="Reverse",AND(COUNT(H22:J22)>0,MIN(H22:J22)<LIM_INS_DC),IF(ISNUMBER(G22),ABS(G22)>LIM_VOC_DEV,FALSE)),"Fail",IF(AND(ISNUMBER(F22),COUNT(H22:J22)=3,K22="OK"),"Pass","Incomplete")))
B23: 9 | G23: =IF(NOT(ISNUMBER(F23)),"",IFERROR(F23/IF(AND(C23<>"",E23<>""),AVERAGEIFS(F$15:F$50,C$15:C$50,C23,E$15:E$50,E23),AVERAGE(F$15:F$50))-1,"")) | N23: =IF(COUNTA(F23,H23:M23)=0,"",IF(OR(K23="Reverse",AND(COUNT(H23:J23)>0,MIN(H23:J23)<LIM_INS_DC),IF(ISNUMBER(G23),ABS(G23)>LIM_VOC_DEV,FALSE)),"Fail",IF(AND(ISNUMBER(F23),COUNT(H23:J23)=3,K23="OK"),"Pass","Incomplete")))
B24: 10 | G24: =IF(NOT(ISNUMBER(F24)),"",IFERROR(F24/IF(AND(C24<>"",E24<>""),AVERAGEIFS(F$15:F$50,C$15:C$50,C24,E$15:E$50,E24),AVERAGE(F$15:F$50))-1,"")) | N24: =IF(COUNTA(F24,H24:M24)=0,"",IF(OR(K24="Reverse",AND(COUNT(H24:J24)>0,MIN(H24:J24)<LIM_INS_DC),IF(ISNUMBER(G24),ABS(G24)>LIM_VOC_DEV,FALSE)),"Fail",IF(AND(ISNUMBER(F24),COUNT(H24:J24)=3,K24="OK"),"Pass","Incomplete")))
B25: 11 | G25: =IF(NOT(ISNUMBER(F25)),"",IFERROR(F25/IF(AND(C25<>"",E25<>""),AVERAGEIFS(F$15:F$50,C$15:C$50,C25,E$15:E$50,E25),AVERAGE(F$15:F$50))-1,"")) | N25: =IF(COUNTA(F25,H25:M25)=0,"",IF(OR(K25="Reverse",AND(COUNT(H25:J25)>0,MIN(H25:J25)<LIM_INS_DC),IF(ISNUMBER(G25),ABS(G25)>LIM_VOC_DEV,FALSE)),"Fail",IF(AND(ISNUMBER(F25),COUNT(H25:J25)=3,K25="OK"),"Pass","Incomplete")))
B26: 12 | G26: =IF(NOT(ISNUMBER(F26)),"",IFERROR(F26/IF(AND(C26<>"",E26<>""),AVERAGEIFS(F$15:F$50,C$15:C$50,C26,E$15:E$50,E26),AVERAGE(F$15:F$50))-1,"")) | N26: =IF(COUNTA(F26,H26:M26)=0,"",IF(OR(K26="Reverse",AND(COUNT(H26:J26)>0,MIN(H26:J26)<LIM_INS_DC),IF(ISNUMBER(G26),ABS(G26)>LIM_VOC_DEV,FALSE)),"Fail",IF(AND(ISNUMBER(F26),COUNT(H26:J26)=3,K26="OK"),"Pass","Incomplete")))
... B50: 36 | G50: =IF(NOT(ISNUMBER(F50)),"",IFERROR(F50/IF(AND(C50<>"",E50<>""),AVERAGEIFS(F$15:F$50,C$15:C$50,C50,E$15:E$50,E50),AVERAGE(F$15:F$50))-1,"")) | N50: =IF(COUNTA(F50,H50:M50)=0,"",IF(OR(K50="Reverse",AND(COUNT(H50:J50)>0,MIN(H50:J50)<LIM_INS_DC),IF(ISNUMBER(G50),ABS(G50)>LIM_VOC_DEV,FALSE)),"Fail",IF(AND(ISNUMBER(F50),COUNT(H50:J50)=3,K50="OK"),"Pass","Incomplete")))
B52: Strings — Pass | F52: =COUNTIF(N15:N50,"Pass") | I52: Strings — Incomplete | L52: =COUNTIF(N15:N50,"Incomplete")
B53: Strings — Fail | F53: =COUNTIF(N15:N50,"Fail")
B55: Officer Name | I55: Signature

Sheet DC INV 02
B2: DC STRING TEST — INV 02
B4: ="Project: "&IF(Cover!$C$7="","(enter on Cover sheet)",Cover!$C$7)&" | Regen Renewables (Pvt) Ltd."
B6: INVERTER DETAILS
B7: Inverter No. | F7: INV 02 | I7: Inverter Location / Room
B8: Make / Model | I8: Serial No.
B9: Rated Capacity (kW) | I9: Date / Time
B10: Tested By | I10: Weather / Irradiance (W/m²)
B11: Total Strings Listed | F11: =COUNT(E15:E50) | I11: Total PV Modules | L11: =SUM(E15:E50)
B12: STRING TESTS — each string is entered ONCE (MPPT / string / module count are not repeated)
B13: STRING DETAILS | F13: NO-LOAD (before energising) | L13: ON-LOAD | N13: RESULT
B14: No. | C14: MPPT | D14: String | E14: PV Modules | F14: Voc (V) | G14: Voc dev. vs group | H14: Insulation + to Earth (MΩ) | I14: Insulation – to Earth (MΩ) | J14: Insulation + to – (MΩ) | K14: Polarity | L14: Operating Voltage (V) | M14: String Current (A) | N14: Result | O14: Remarks
B15: 1 | G15: =IF(NOT(ISNUMBER(F15)),"",IFERROR(F15/IF(AND(C15<>"",E15<>""),AVERAGEIFS(F$15:F$50,C$15:C$50,C15,E$15:E$50,E15),AVERAGE(F$15:F$50))-1,"")) | N15: =IF(COUNTA(F15,H15:M15)=0,"",IF(OR(K15="Reverse",AND(COUNT(H15:J15)>0,MIN(H15:J15)<LIM_INS_DC),IF(ISNUMBER(G15),ABS(G15)>LIM_VOC_DEV,FALSE)),"Fail",IF(AND(ISNUMBER(F15),COUNT(H15:J15)=3,K15="OK"),"Pass","Incomplete")))
B16: 2 | G16: =IF(NOT(ISNUMBER(F16)),"",IFERROR(F16/IF(AND(C16<>"",E16<>""),AVERAGEIFS(F$15:F$50,C$15:C$50,C16,E$15:E$50,E16),AVERAGE(F$15:F$50))-1,"")) | N16: =IF(COUNTA(F16,H16:M16)=0,"",IF(OR(K16="Reverse",AND(COUNT(H16:J16)>0,MIN(H16:J16)<LIM_INS_DC),IF(ISNUMBER(G16),ABS(G16)>LIM_VOC_DEV,FALSE)),"Fail",IF(AND(ISNUMBER(F16),COUNT(H16:J16)=3,K16="OK"),"Pass","Incomplete")))
B17: 3 | G17: =IF(NOT(ISNUMBER(F17)),"",IFERROR(F17/IF(AND(C17<>"",E17<>""),AVERAGEIFS(F$15:F$50,C$15:C$50,C17,E$15:E$50,E17),AVERAGE(F$15:F$50))-1,"")) | N17: =IF(COUNTA(F17,H17:M17)=0,"",IF(OR(K17="Reverse",AND(COUNT(H17:J17)>0,MIN(H17:J17)<LIM_INS_DC),IF(ISNUMBER(G17),ABS(G17)>LIM_VOC_DEV,FALSE)),"Fail",IF(AND(ISNUMBER(F17),COUNT(H17:J17)=3,K17="OK"),"Pass","Incomplete")))
B18: 4 | G18: =IF(NOT(ISNUMBER(F18)),"",IFERROR(F18/IF(AND(C18<>"",E18<>""),AVERAGEIFS(F$15:F$50,C$15:C$50,C18,E$15:E$50,E18),AVERAGE(F$15:F$50))-1,"")) | N18: =IF(COUNTA(F18,H18:M18)=0,"",IF(OR(K18="Reverse",AND(COUNT(H18:J18)>0,MIN(H18:J18)<LIM_INS_DC),IF(ISNUMBER(G18),ABS(G18)>LIM_VOC_DEV,FALSE)),"Fail",IF(AND(ISNUMBER(F18),COUNT(H18:J18)=3,K18="OK"),"Pass","Incomplete")))
B19: 5 | G19: =IF(NOT(ISNUMBER(F19)),"",IFERROR(F19/IF(AND(C19<>"",E19<>""),AVERAGEIFS(F$15:F$50,C$15:C$50,C19,E$15:E$50,E19),AVERAGE(F$15:F$50))-1,"")) | N19: =IF(COUNTA(F19,H19:M19)=0,"",IF(OR(K19="Reverse",AND(COUNT(H19:J19)>0,MIN(H19:J19)<LIM_INS_DC),IF(ISNUMBER(G19),ABS(G19)>LIM_VOC_DEV,FALSE)),"Fail",IF(AND(ISNUMBER(F19),COUNT(H19:J19)=3,K19="OK"),"Pass","Incomplete")))
B20: 6 | G20: =IF(NOT(ISNUMBER(F20)),"",IFERROR(F20/IF(AND(C20<>"",E20<>""),AVERAGEIFS(F$15:F$50,C$15:C$50,C20,E$15:E$50,E20),AVERAGE(F$15:F$50))-1,"")) | N20: =IF(COUNTA(F20,H20:M20)=0,"",IF(OR(K20="Reverse",AND(COUNT(H20:J20)>0,MIN(H20:J20)<LIM_INS_DC),IF(ISNUMBER(G20),ABS(G20)>LIM_VOC_DEV,FALSE)),"Fail",IF(AND(ISNUMBER(F20),COUNT(H20:J20)=3,K20="OK"),"Pass","Incomplete")))
B21: 7 | G21: =IF(NOT(ISNUMBER(F21)),"",IFERROR(F21/IF(AND(C21<>"",E21<>""),AVERAGEIFS(F$15:F$50,C$15:C$50,C21,E$15:E$50,E21),AVERAGE(F$15:F$50))-1,"")) | N21: =IF(COUNTA(F21,H21:M21)=0,"",IF(OR(K21="Reverse",AND(COUNT(H21:J21)>0,MIN(H21:J21)<LIM_INS_DC),IF(ISNUMBER(G21),ABS(G21)>LIM_VOC_DEV,FALSE)),"Fail",IF(AND(ISNUMBER(F21),COUNT(H21:J21)=3,K21="OK"),"Pass","Incomplete")))
B22: 8 | G22: =IF(NOT(ISNUMBER(F22)),"",IFERROR(F22/IF(AND(C22<>"",E22<>""),AVERAGEIFS(F$15:F$50,C$15:C$50,C22,E$15:E$50,E22),AVERAGE(F$15:F$50))-1,"")) | N22: =IF(COUNTA(F22,H22:M22)=0,"",IF(OR(K22="Reverse",AND(COUNT(H22:J22)>0,MIN(H22:J22)<LIM_INS_DC),IF(ISNUMBER(G22),ABS(G22)>LIM_VOC_DEV,FALSE)),"Fail",IF(AND(ISNUMBER(F22),COUNT(H22:J22)=3,K22="OK"),"Pass","Incomplete")))
B23: 9 | G23: =IF(NOT(ISNUMBER(F23)),"",IFERROR(F23/IF(AND(C23<>"",E23<>""),AVERAGEIFS(F$15:F$50,C$15:C$50,C23,E$15:E$50,E23),AVERAGE(F$15:F$50))-1,"")) | N23: =IF(COUNTA(F23,H23:M23)=0,"",IF(OR(K23="Reverse",AND(COUNT(H23:J23)>0,MIN(H23:J23)<LIM_INS_DC),IF(ISNUMBER(G23),ABS(G23)>LIM_VOC_DEV,FALSE)),"Fail",IF(AND(ISNUMBER(F23),COUNT(H23:J23)=3,K23="OK"),"Pass","Incomplete")))
B24: 10 | G24: =IF(NOT(ISNUMBER(F24)),"",IFERROR(F24/IF(AND(C24<>"",E24<>""),AVERAGEIFS(F$15:F$50,C$15:C$50,C24,E$15:E$50,E24),AVERAGE(F$15:F$50))-1,"")) | N24: =IF(COUNTA(F24,H24:M24)=0,"",IF(OR(K24="Reverse",AND(COUNT(H24:J24)>0,MIN(H24:J24)<LIM_INS_DC),IF(ISNUMBER(G24),ABS(G24)>LIM_VOC_DEV,FALSE)),"Fail",IF(AND(ISNUMBER(F24),COUNT(H24:J24)=3,K24="OK"),"Pass","Incomplete")))
B25: 11 | G25: =IF(NOT(ISNUMBER(F25)),"",IFERROR(F25/IF(AND(C25<>"",E25<>""),AVERAGEIFS(F$15:F$50,C$15:C$50,C25,E$15:E$50,E25),AVERAGE(F$15:F$50))-1,"")) | N25: =IF(COUNTA(F25,H25:M25)=0,"",IF(OR(K25="Reverse",AND(COUNT(H25:J25)>0,MIN(H25:J25)<LIM_INS_DC),IF(ISNUMBER(G25),ABS(G25)>LIM_VOC_DEV,FALSE)),"Fail",IF(AND(ISNUMBER(F25),COUNT(H25:J25)=3,K25="OK"),"Pass","Incomplete")))
B26: 12 | G26: =IF(NOT(ISNUMBER(F26)),"",IFERROR(F26/IF(AND(C26<>"",E26<>""),AVERAGEIFS(F$15:F$50,C$15:C$50,C26,E$15:E$50,E26),AVERAGE(F$15:F$50))-1,"")) | N26: =IF(COUNTA(F26,H26:M26)=0,"",IF(OR(K26="Reverse",AND(COUNT(H26:J26)>0,MIN(H26:J26)<LIM_INS_DC),IF(ISNUMBER(G26),ABS(G26)>LIM_VOC_DEV,FALSE)),"Fail",IF(AND(ISNUMBER(F26),COUNT(H26:J26)=3,K26="OK"),"Pass","Incomplete")))
... B50: 36 | G50: =IF(NOT(ISNUMBER(F50)),"",IFERROR(F50/IF(AND(C50<>"",E50<>""),AVERAGEIFS(F$15:F$50,C$15:C$50,C50,E$15:E$50,E50),AVERAGE(F$15:F$50))-1,"")) | N50: =IF(COUNTA(F50,H50:M50)=0,"",IF(OR(K50="Reverse",AND(COUNT(H50:J50)>0,MIN(H50:J50)<LIM_INS_DC),IF(ISNUMBER(G50),ABS(G50)>LIM_VOC_DEV,FALSE)),"Fail",IF(AND(ISNUMBER(F50),COUNT(H50:J50)=3,K50="OK"),"Pass","Incomplete")))
B52: Strings — Pass | F52: =COUNTIF(N15:N50,"Pass") | I52: Strings — Incomplete | L52: =COUNTIF(N15:N50,"Incomplete")
B53: Strings — Fail | F53: =COUNTIF(N15:N50,"Fail")
B55: Officer Name | I55: Signature

Sheet AC Output
B2: AC OUTPUT TEST (grid no-load and inverter on-load)
B4: ="Project: "&IF(Cover!$C$7="","(enter on Cover sheet)",Cover!$C$7)&" | Regen Renewables (Pvt) Ltd."
B6: AC SIDE READINGS — first row = grid side with inverters OFF, then each inverter ON-LOAD
B7: Date | H7: Tested By
B9: POINT | E9: VOLTAGE L–N (V) | H9: CURRENT (A) | K9: POWER | N9: RESULT
B10: No. | C10: Grid / Inverter & Room | D10: Time | E10: L1 | F10: L2 | G10: L3 | H10: L1 | I10: L2 | J10: L3 | K10: Active Power (kW) | L10: PF | M10: Freq (Hz) | N10: Result | O10: Remarks
B11: 1 | C11: Grid side (no load) | N11: =IF(COUNT(E11:G11)=0,"",IF(OR(MAX(E11:G11)>LIM_VNOM*(1+LIM_VTOL),MIN(E11:G11)<LIM_VNOM*(1-LIM_VTOL),IF(ISNUMBER(M11),ABS(M11-LIM_FNOM)>LIM_FTOL,FALSE)),"Fail","Pass"))
B12: 2 | N12: =IF(COUNT(E12:G12)=0,"",IF(OR(MAX(E12:G12)>LIM_VNOM*(1+LIM_VTOL),MIN(E12:G12)<LIM_VNOM*(1-LIM_VTOL),IF(ISNUMBER(M12),ABS(M12-LIM_FNOM)>LIM_FTOL,FALSE)),"Fail","Pass"))
B13: 3 | N13: =IF(COUNT(E13:G13)=0,"",IF(OR(MAX(E13:G13)>LIM_VNOM*(1+LIM_VTOL),MIN(E13:G13)<LIM_VNOM*(1-LIM_VTOL),IF(ISNUMBER(M13),ABS(M13-LIM_FNOM)>LIM_FTOL,FALSE)),"Fail","Pass"))
B14: 4 | N14: =IF(COUNT(E14:G14)=0,"",IF(OR(MAX(E14:G14)>LIM_VNOM*(1+LIM_VTOL),MIN(E14:G14)<LIM_VNOM*(1-LIM_VTOL),IF(ISNUMBER(M14),ABS(M14-LIM_FNOM)>LIM_FTOL,FALSE)),"Fail","Pass"))
B15: 5 | N15: =IF(COUNT(E15:G15)=0,"",IF(OR(MAX(E15:G15)>LIM_VNOM*(1+LIM_VTOL),MIN(E15:G15)<LIM_VNOM*(1-LIM_VTOL),IF(ISNUMBER(M15),ABS(M15-LIM_FNOM)>LIM_FTOL,FALSE)),"Fail","Pass"))
B16: 6 | N16: =IF(COUNT(E16:G16)=0,"",IF(OR(MAX(E16:G16)>LIM_VNOM*(1+LIM_VTOL),MIN(E16:G16)<LIM_VNOM*(1-LIM_VTOL),IF(ISNUMBER(M16),ABS(M16-LIM_FNOM)>LIM_FTOL,FALSE)),"Fail","Pass"))
B17: 7 | N17: =IF(COUNT(E17:G17)=0,"",IF(OR(MAX(E17:G17)>LIM_VNOM*(1+LIM_VTOL),MIN(E17:G17)<LIM_VNOM*(1-LIM_VTOL),IF(ISNUMBER(M17),ABS(M17-LIM_FNOM)>LIM_FTOL,FALSE)),"Fail","Pass"))
B18: 8 | N18: =IF(COUNT(E18:G18)=0,"",IF(OR(MAX(E18:G18)>LIM_VNOM*(1+LIM_VTOL),MIN(E18:G18)<LIM_VNOM*(1-LIM_VTOL),IF(ISNUMBER(M18),ABS(M18-LIM_FNOM)>LIM_FTOL,FALSE)),"Fail","Pass"))
B19: 9 | N19: =IF(COUNT(E19:G19)=0,"",IF(OR(MAX(E19:G19)>LIM_VNOM*(1+LIM_VTOL),MIN(E19:G19)<LIM_VNOM*(1-LIM_VTOL),IF(ISNUMBER(M19),ABS(M19-LIM_FNOM)>LIM_FTOL,FALSE)),"Fail","Pass"))
B20: 10 | N20: =IF(COUNT(E20:G20)=0,"",IF(OR(MAX(E20:G20)>LIM_VNOM*(1+LIM_VTOL),MIN(E20:G20)<LIM_VNOM*(1-LIM_VTOL),IF(ISNUMBER(M20),ABS(M20-LIM_FNOM)>LIM_FTOL,FALSE)),"Fail","Pass"))
B21: 11 | N21: =IF(COUNT(E21:G21)=0,"",IF(OR(MAX(E21:G21)>LIM_VNOM*(1+LIM_VTOL),MIN(E21:G21)<LIM_VNOM*(1-LIM_VTOL),IF(ISNUMBER(M21),ABS(M21-LIM_FNOM)>LIM_FTOL,FALSE)),"Fail","Pass"))
B22: 12 | N22: =IF(COUNT(E22:G22)=0,"",IF(OR(MAX(E22:G22)>LIM_VNOM*(1+LIM_VTOL),MIN(E22:G22)<LIM_VNOM*(1-LIM_VTOL),IF(ISNUMBER(M22),ABS(M22-LIM_FNOM)>LIM_FTOL,FALSE)),"Fail","Pass"))
B24: Total plant AC power (kW) | F24: =SUM(K11:K22)
B25: Result checks every phase against the voltage window and the frequency against the tolerance set on “Equipment and Limits”. Leave unused phases blank for single-phase inverters.
B27: Officer Name | I27: Signature

Sheet AC Insulation and Earthing
B2: AC INSULATION & EARTHING TEST
B4: ="Project: "&IF(Cover!$C$7="","(enter on Cover sheet)",Cover!$C$7)&" | Regen Renewables (Pvt) Ltd."
B6: AC SIDE INSULATION RESISTANCE (MΩ) — one row per inverter / circuit (grid side and main panel can be added as extra rows)
B7: Date | G7: Test Voltage (V) | L7: Tested By
B9: No. | C9: Inverter / Circuit | D9: L1–L2 | E9: L1–L3 | F9: L2–L3 | G9: L1–N | H9: L2–N | I9: L3–N | J9: L1–E | K9: L2–E | L9: L3–E | M9: N–E | N9: Result | O9: Remarks
B10: 1 | N10: =IF(COUNTA(D10:M10)=0,"",IF(AND(COUNT(D10:M10)>0,MIN(D10:M10)<LIM_INS_AC),"Fail",IF(COUNTA(D10:M10)=10,"Pass","Incomplete")))
B11: 2 | N11: =IF(COUNTA(D11:M11)=0,"",IF(AND(COUNT(D11:M11)>0,MIN(D11:M11)<LIM_INS_AC),"Fail",IF(COUNTA(D11:M11)=10,"Pass","Incomplete")))
B12: 3 | N12: =IF(COUNTA(D12:M12)=0,"",IF(AND(COUNT(D12:M12)>0,MIN(D12:M12)<LIM_INS_AC),"Fail",IF(COUNTA(D12:M12)=10,"Pass","Incomplete")))
B13: 4 | N13: =IF(COUNTA(D13:M13)=0,"",IF(AND(COUNT(D13:M13)>0,MIN(D13:M13)<LIM_INS_AC),"Fail",IF(COUNTA(D13:M13)=10,"Pass","Incomplete")))
B14: 5 | N14: =IF(COUNTA(D14:M14)=0,"",IF(AND(COUNT(D14:M14)>0,MIN(D14:M14)<LIM_INS_AC),"Fail",IF(COUNTA(D14:M14)=10,"Pass","Incomplete")))
B15: 6 | N15: =IF(COUNTA(D15:M15)=0,"",IF(AND(COUNT(D15:M15)>0,MIN(D15:M15)<LIM_INS_AC),"Fail",IF(COUNTA(D15:M15)=10,"Pass","Incomplete")))
B16: 7 | N16: =IF(COUNTA(D16:M16)=0,"",IF(AND(COUNT(D16:M16)>0,MIN(D16:M16)<LIM_INS_AC),"Fail",IF(COUNTA(D16:M16)=10,"Pass","Incomplete")))
B17: 8 | N17: =IF(COUNTA(D17:M17)=0,"",IF(AND(COUNT(D17:M17)>0,MIN(D17:M17)<LIM_INS_AC),"Fail",IF(COUNTA(D17:M17)=10,"Pass","Incomplete")))
B18: 9 | N18: =IF(COUNTA(D18:M18)=0,"",IF(AND(COUNT(D18:M18)>0,MIN(D18:M18)<LIM_INS_AC),"Fail",IF(COUNTA(D18:M18)=10,"Pass","Incomplete")))
B19: 10 | N19: =IF(COUNTA(D19:M19)=0,"",IF(AND(COUNT(D19:M19)>0,MIN(D19:M19)<LIM_INS_AC),"Fail",IF(COUNTA(D19:M19)=10,"Pass","Incomplete")))
B20: 11 | N20: =IF(COUNTA(D20:M20)=0,"",IF(AND(COUNT(D20:M20)>0,MIN(D20:M20)<LIM_INS_AC),"Fail",IF(COUNTA(D20:M20)=10,"Pass","Incomplete")))
B21: 12 | N21: =IF(COUNTA(D21:M21)=0,"",IF(AND(COUNT(D21:M21)>0,MIN(D21:M21)<LIM_INS_AC),"Fail",IF(COUNTA(D21:M21)=10,"Pass","Incomplete")))
B22: Single-phase: type N/A in the cells that do not apply. If the tester shows “>” or “OL”, type the highest number displayed.
B24: EARTHING TEST
B25: Rod No. | C25: Location | D25: Value (Ω) | G25: Result | I25: Remarks
B26: 1 | G26: =IF(NOT(ISNUMBER(D26)),"",IF(D26<=LIM_EARTH,"Pass","Fail"))
B27: 2 | G27: =IF(NOT(ISNUMBER(D27)),"",IF(D27<=LIM_EARTH,"Pass","Fail"))
B28: 3 | G28: =IF(NOT(ISNUMBER(D28)),"",IF(D28<=LIM_EARTH,"Pass","Fail"))
B29: 4 | G29: =IF(NOT(ISNUMBER(D29)),"",IF(D29<=LIM_EARTH,"Pass","Fail"))
B30: 5 | G30: =IF(NOT(ISNUMBER(D30)),"",IF(D30<=LIM_EARTH,"Pass","Fail"))
B31: 6 | G31: =IF(NOT(ISNUMBER(D31)),"",IF(D31<=LIM_EARTH,"Pass","Fail"))
B32: 7 | G32: =IF(NOT(ISNUMBER(D32)),"",IF(D32<=LIM_EARTH,"Pass","Fail"))
B33: 8 | G33: =IF(NOT(ISNUMBER(D33)),"",IF(D33<=LIM_EARTH,"Pass","Fail"))
B35: Officer Name | I35: Signature

Sheet Thermal Imaging
B2: THERMAL IMAGING TEST
B4: ="Project: "&IF(Cover!$C$7="","(enter on Cover sheet)",Cover!$C$7)&" | Regen Renewables (Pvt) Ltd."
B6: TEST CONDITIONS
B7: Date | F7: Ambient Temp (°C)
B8: Irradiance (W/m²) | F8: Tested By
B10: SOLAR PANELS — CRITICAL / HOT PANELS
B11: No. | C11: Inverter / String | D11: Panel Serial No. | E11: Time | F11: Temp (°C) | G11: ΔT vs ambient (°C) | H11: Result | I11: Comment
B12: 1 | G12: =IF(AND(ISNUMBER(F12),ISNUMBER($H$7)),F12-$H$7,"") | H12: =IF(NOT(ISNUMBER(F12)),"",IF(NOT(ISNUMBER(G12)),"Incomplete",IF(G12>LIM_DT,"Fail","Pass")))
B13: 2 | G13: =IF(AND(ISNUMBER(F13),ISNUMBER($H$7)),F13-$H$7,"") | H13: =IF(NOT(ISNUMBER(F13)),"",IF(NOT(ISNUMBER(G13)),"Incomplete",IF(G13>LIM_DT,"Fail","Pass")))
B14: 3 | G14: =IF(AND(ISNUMBER(F14),ISNUMBER($H$7)),F14-$H$7,"") | H14: =IF(NOT(ISNUMBER(F14)),"",IF(NOT(ISNUMBER(G14)),"Incomplete",IF(G14>LIM_DT,"Fail","Pass")))
B15: 4 | G15: =IF(AND(ISNUMBER(F15),ISNUMBER($H$7)),F15-$H$7,"") | H15: =IF(NOT(ISNUMBER(F15)),"",IF(NOT(ISNUMBER(G15)),"Incomplete",IF(G15>LIM_DT,"Fail","Pass")))
B16: 5 | G16: =IF(AND(ISNUMBER(F16),ISNUMBER($H$7)),F16-$H$7,"") | H16: =IF(NOT(ISNUMBER(F16)),"",IF(NOT(ISNUMBER(G16)),"Incomplete",IF(G16>LIM_DT,"Fail","Pass")))
B17: 6 | G17: =IF(AND(ISNUMBER(F17),ISNUMBER($H$7)),F17-$H$7,"") | H17: =IF(NOT(ISNUMBER(F17)),"",IF(NOT(ISNUMBER(G17)),"Incomplete",IF(G17>LIM_DT,"Fail","Pass")))
B18: 7 | G18: =IF(AND(ISNUMBER(F18),ISNUMBER($H$7)),F18-$H$7,"") | H18: =IF(NOT(ISNUMBER(F18)),"",IF(NOT(ISNUMBER(G18)),"Incomplete",IF(G18>LIM_DT,"Fail","Pass")))
B19: 8 | G19: =IF(AND(ISNUMBER(F19),ISNUMBER($H$7)),F19-$H$7,"") | H19: =IF(NOT(ISNUMBER(F19)),"",IF(NOT(ISNUMBER(G19)),"Incomplete",IF(G19>LIM_DT,"Fail","Pass")))
B20: 9 | G20: =IF(AND(ISNUMBER(F20),ISNUMBER($H$7)),F20-$H$7,"") | H20: =IF(NOT(ISNUMBER(F20)),"",IF(NOT(ISNUMBER(G20)),"Incomplete",IF(G20>LIM_DT,"Fail","Pass")))
B21: 10 | G21: =IF(AND(ISNUMBER(F21),ISNUMBER($H$7)),F21-$H$7,"") | H21: =IF(NOT(ISNUMBER(F21)),"",IF(NOT(ISNUMBER(G21)),"Incomplete",IF(G21>LIM_DT,"Fail","Pass")))
B23: INVERTERS
B24: No. | C24: Inverter / Room | D24: Point Inspected | E24: Time | F24: Temp (°C) | G24: ΔT vs ambient (°C) | H24: Result | I24: Comment
B25: 1 | G25: =IF(AND(ISNUMBER(F25),ISNUMBER($H$7)),F25-$H$7,"") | H25: =IF(NOT(ISNUMBER(F25)),"",IF(NOT(ISNUMBER(G25)),"Incomplete",IF(G25>LIM_DT,"Fail","Pass")))
B26: 2 | G26: =IF(AND(ISNUMBER(F26),ISNUMBER($H$7)),F26-$H$7,"") | H26: =IF(NOT(ISNUMBER(F26)),"",IF(NOT(ISNUMBER(G26)),"Incomplete",IF(G26>LIM_DT,"Fail","Pass")))
B27: 3 | G27: =IF(AND(ISNUMBER(F27),ISNUMBER($H$7)),F27-$H$7,"") | H27: =IF(NOT(ISNUMBER(F27)),"",IF(NOT(ISNUMBER(G27)),"Incomplete",IF(G27>LIM_DT,"Fail","Pass")))
B28: 4 | G28: =IF(AND(ISNUMBER(F28),ISNUMBER($H$7)),F28-$H$7,"") | H28: =IF(NOT(ISNUMBER(F28)),"",IF(NOT(ISNUMBER(G28)),"Incomplete",IF(G28>LIM_DT,"Fail","Pass")))
B29: 5 | G29: =IF(AND(ISNUMBER(F29),ISNUMBER($H$7)),F29-$H$7,"") | H29: =IF(NOT(ISNUMBER(F29)),"",IF(NOT(ISNUMBER(G29)),"Incomplete",IF(G29>LIM_DT,"Fail","Pass")))
B30: 6 | G30: =IF(AND(ISNUMBER(F30),ISNUMBER($H$7)),F30-$H$7,"") | H30: =IF(NOT(ISNUMBER(F30)),"",IF(NOT(ISNUMBER(G30)),"Incomplete",IF(G30>LIM_DT,"Fail","Pass")))
B31: 7 | G31: =IF(AND(ISNUMBER(F31),ISNUMBER($H$7)),F31-$H$7,"") | H31: =IF(NOT(ISNUMBER(F31)),"",IF(NOT(ISNUMBER(G31)),"Incomplete",IF(G31>LIM_DT,"Fail","Pass")))
B32: 8 | G32: =IF(AND(ISNUMBER(F32),ISNUMBER($H$7)),F32-$H$7,"") | H32: =IF(NOT(ISNUMBER(F32)),"",IF(NOT(ISNUMBER(G32)),"Incomplete",IF(G32>LIM_DT,"Fail","Pass")))
B34: SWITCHGEAR PANEL — BREAKERS
B35: No. | C35: Breaker (Main / Inverter) | D35: Rating / Ref | E35: Time | F35: IN Temp (°C) | G35: OUT Temp (°C) | H35: Result | I35: Comment
B36: 1 | C36: Main Breaker | H36: =IF(COUNT(F36:G36)=0,"",IF(NOT(ISNUMBER($H$7)),"Incomplete",IF(MAX(F36:G36)-$H$7>LIM_DT,"Fail","Pass")))
B37: 2 | H37: =IF(COUNT(F37:G37)=0,"",IF(NOT(ISNUMBER($H$7)),"Incomplete",IF(MAX(F37:G37)-$H$7>LIM_DT,"Fail","Pass")))
B38: 3 | H38: =IF(COUNT(F38:G38)=0,"",IF(NOT(ISNUMBER($H$7)),"Incomplete",IF(MAX(F38:G38)-$H$7>LIM_DT,"Fail","Pass")))
B39: 4 | H39: =IF(COUNT(F39:G39)=0,"",IF(NOT(ISNUMBER($H$7)),"Incomplete",IF(MAX(F39:G39)-$H$7>LIM_DT,"Fail","Pass")))
B40: 5 | H40: =IF(COUNT(F40:G40)=0,"",IF(NOT(ISNUMBER($H$7)),"Incomplete",IF(MAX(F40:G40)-$H$7>LIM_DT,"Fail","Pass")))
B41: 6 | H41: =IF(COUNT(F41:G41)=0,"",IF(NOT(ISNUMBER($H$7)),"Incomplete",IF(MAX(F41:G41)-$H$7>LIM_DT,"Fail","Pass")))
B42: 7 | H42: =IF(COUNT(F42:G42)=0,"",IF(NOT(ISNUMBER($H$7)),"Incomplete",IF(MAX(F42:G42)-$H$7>LIM_DT,"Fail","Pass")))
B43: 8 | H43: =IF(COUNT(F43:G43)=0,"",IF(NOT(ISNUMBER($H$7)),"Incomplete",IF(MAX(F43:G43)-$H$7>LIM_DT,"Fail","Pass")))
B44: 9 | H44: =IF(COUNT(F44:G44)=0,"",IF(NOT(ISNUMBER($H$7)),"Incomplete",IF(MAX(F44:G44)-$H$7>LIM_DT,"Fail","Pass")))
B45: Result = Fail when the hottest reading is more than the ΔT limit (see “Equipment and Limits”) above ambient. Attach thermal images to the report separately.
B47: Officer Name | E47: Signature

Sheet Battery
B2: BATTERY TEST (hybrid / battery-backed systems)
B4: ="Project: "&IF(Cover!$C$7="","(enter on Cover sheet)",Cover!$C$7)&" | Regen Renewables (Pvt) Ltd."
B6: BATTERY SYSTEM DETAILS
B7: Battery Brand & Model | F7: No. of Modules / Racks
B8: Battery Type | F8: No. of Battery Strings
B9: Bank Capacity (kWh) | F9: BMS Model
B10: Nominal Voltage (V) | F10: Date / Tested By
B12: BATTERY MODULE / STRING VOLTAGE & INSULATION
B13: No. | C13: Module / Rack No. | D13: String No. | E13: Nominal Voltage (V) | F13: Measured Voltage (V) | G13: Insulation (MΩ) | H13: Status | I13: Remarks
B14: 1
B15: 2
B16: 3
B17: 4
B18: 5
B19: 6
B20: 7
B21: 8
B22: 9
B23: 10
B24: 11
B25: 12
... B29: 16
B31: BATTERY PROTECTION & BMS SETTINGS
B32: No. | C32: Parameter | D32: Set / Measured | E32: Standard / Ref | F32: Result | G32: Remarks
B33: 1 | C33: Over Voltage Protection (V)
B34: 2 | C34: Under Voltage Protection (V)
B35: 3 | C35: Over Current Protection (A)
B36: 4 | C36: Over Temperature Protection (°C)
B37: 5 | C37: Under Temperature Protection (°C)
B38: 6 | C38: Cell Balancing Function Test
B39: 7 | C39: SOC Display Accuracy
B40: 8 | C40: BMS Communication / Monitoring Test
B41: 9 | C41: Battery Emergency Shutdown Test
B43: CHARGE / DISCHARGE / BACKUP TEST
B44: Test | D44: Start Time | E44: End Time | F44: Start / End SOC (%) | G44: Start / End Voltage (V) | H44: Current (A) | I44: Duration (min) | J44: Remarks
B45: Charge Test
B46: Discharge Test
B47: Backup / Off-Grid Test (grid failure simulation)
B49: Officer Name | F49: Signature

Sheet Protection and Grid
B2: PROTECTION & GRID SETTINGS VERIFICATION
B4: ="Project: "&IF(Cover!$C$7="","(enter on Cover sheet)",Cover!$C$7)&" | Regen Renewables (Pvt) Ltd."
B6: No. | C6: Parameter | D6: Set / Measured Value | E6: Standard / Reference | F6: Result | G6: Remarks
B7: 1 | C7: Over Voltage Protection Trip (V)
B8: 2 | C8: Under Voltage Protection Trip (V)
B9: 3 | C9: Over Frequency Protection Trip (Hz)
B10: 4 | C10: Under Frequency Protection Trip (Hz)
B11: 5 | C11: Anti-Islanding Protection Test
B12: 6 | C12: Reconnection Time Delay (s)
B13: 7 | C13: Export Power Limit Setting (kW / %)
B14: 8 | C14: RCD / ELCB Rated Trip Current (mA)
B15: 9 | C15: RCD / ELCB Trip Test Result
B16: 10 | C16: Earth Fault Protection Test
B17: 11 | C17: Remote Shutdown / Emergency Stop Test
B18: 12 | C18: Communication Module (WiFi / 4G / RS485) Test
... B20: 14 | C20: Inverter Firmware Version(s)
B22: Verified By | E22: Date

Sheet Punch List
B2: PUNCH LIST / SNAG LIST
B4: ="Project: "&IF(Cover!$C$7="","(enter on Cover sheet)",Cover!$C$7)&" | Regen Renewables (Pvt) Ltd."
B6: No. | C6: Date Raised | D6: Location / Inverter | E6: Issue Description | F6: Category | G6: Raised By | H6: Corrective Action | I6: Responsible | J6: Target Date | K6: Status | L6: Closed Date
B7: 1
B8: 2
B9: 3
B10: 4
B11: 5
B12: 6
B13: 7
B14: 8
B15: 9
B16: 10
B17: 11
B18: 12
... B24: 18

Sheet Sign-Off
B2: FINAL COMMISSIONING SIGN-OFF
B4: ="Project: "&IF(Cover!$C$7="","(enter on Cover sheet)",Cover!$C$7)&" | Regen Renewables (Pvt) Ltd."
B6: Overall Commissioning Result | C6: ='Summary'!$H$21
B7: Commissioned Date
B8: Commissioned Officer Name | E8: Signature
B10: SIGN-OFF
B11: Role | C11: Name | D11: Company | E11: Signature | F11: Date
B12: Commissioning Engineer
B13: QA / QC Engineer
B14: Client Representative / Consultant
B15: Site Safety Officer
B17: HANDOVER CHECKLIST
B18: Item | E18: Status
B19: As-built drawings provided
B20: O&M manual provided
B21: Warranty certificates provided
B22: Spare parts list provided
B23: O&M training conducted
B24: Monitoring portal access provided
B25: Test certificates / thermal images attached
B27: COMMENTS
